Workbook

Sheet Products
A1: Short Name | B1: Title | C1: New SKU | D1: Old SKU | E1: X Code (Type) | F1: X Desc | G1: Y Code Subtype) | H1: Y desc | I1: Z Code (Variation) | J1: Z Desc | K1: A Code (Quantity) | L1: A Desc
A2: 1oz D8 Advanced Tincture | B2: Delta 8 1oz THC Advanced Formula Tincture (40 mg/mL) | C2: T-D8AdvancedFormula
A3: Silver Bundle Package | B3: =F3&": "&H3&", "&J3&", "&L3 -> Bundle: Bundles, Lotion Bar, Honeysticks plus tincture, 1400mg | D3: =E3&G3&I3&K3 -> 8112 | E3: 8 | F3: Bundle | G3: 1 | H3: Bundles | I3: 1 | J3: Lotion Bar, Honeysticks plus tincture | K3: 2 | L3: 1400mg
A4: Gold Bundle Package | B4: =F4&": "&H4&", "&J4&", "&L4 -> Bundle: Bundles, Lotion Bar, Honeysticks plus tincture, 2800mg | D4: =E4&G4&I4&K4 -> 8111 | E4: 8 | F4: Bundle | G4: 1 | H4: Bundles | I4: 1 | J4: Lotion Bar, Honeysticks plus tincture | K4: 1 | L4: 2800mg
A5: Bronze Bundle Package | B5: =F5&": "&H5&", "&J5&", "&L5 -> Bundle: Bundles, Lotion Bar, Honeysticks plus tincture, 700mg | D5: =E5&G5&I5&K5 -> 8113 | E5: 8 | F5: Bundle | G5: 1 | H5: Bundles | I5: 1 | J5: Lotion Bar, Honeysticks plus tincture | K5: 3 | L5: 700mg
B6: =F6&": "&H6&", "&J6&", "&L6 -> Bundle: Gift Packs, 1/2oz adv tincture, 1 lotion bar, 10 taffies, Default | D6: =E6&G6&I6&K6 -> 8221 | E6: 8 | F6: Bundle | G6: 2 | H6: Gift Packs | I6: 2 | J6: 1/2oz adv tincture, 1 lotion bar, 10 taffies | K6: 1 | L6: Default
B7: =F7&": "&H7&", "&J7&", "&L7 -> Bundle: Gift Packs, 30 ct gelcaps, 1 lotion bar, 10 taffies, Default | D7: =E7&G7&I7&K7 -> 8211 | E7: 8 | F7: Bundle | G7: 2 | H7: Gift Packs | I7: 1 | J7: 30 ct gelcaps, 1 lotion bar, 10 taffies | K7: 1 | L7: Default
B8: =F8&": "&H8&", "&J8&", "&L8 -> Bundle: Gift Packs, taffies and lotion bar plus another product, 1/2oz advanced tincture | D8: =E8&G8&I8&K8 -> 8211 | E8: 8 | F8: Bundle | G8: 2 | H8: Gift Packs | I8: 1 | J8: taffies and lotion bar plus another product | K8: 1 | L8: 1/2oz advanced tincture
B9: =F9&": "&H9&", "&J9&", "&L9 -> Bundle: Gift Packs, taffies and lotion bar plus another product, 30ct advanced gelcaps | D9: =E9&G9&I9&K9 -> 8212 | E9: 8 | F9: Bundle | G9: 2 | H9: Gift Packs | I9: 1 | J9: taffies and lotion bar plus another product | K9: 2 | L9: 30ct advanced gelcaps
A10: Gold Bundle | B10: =F10&": "&H10&", "&J10&", "&L10 -> Bundle: Starter Packs, Gold Package (2800, lotion bar & honeysticks), Default | D10: =E10&G10&I10&K10 -> 8111 | E10: 8 | F10: Bundle | G10: 1 | H10: Starter Packs | I10: 1 | J10: Gold Package (2800, lotion bar & honeysticks) | K10: 1 | L10: Default
A11: Green Apple Supreme THC Free Gummies (10CT) | C11: E-IsoSupremeGummies10Ct
A12: Green Apple Supreme THC Free Gummies (30CT) | C12: E-IsoSupremeGummies30Ct
A13: Blue Raspberry Delta 8 Gummies (30CT) | B13: =F13&": "&H13&", "&J13&", "&L13 -> Edible: Gummies, Delta 8 Infused (40MG), 30 count blue raspberry | C13: E-BlueRasD8Gummies30Ct | D13: =E13&G13&I13&K13 -> 338R30 | E13: 3 | F13: Edible | G13: 3 | H13: Gummies | I13: 8 | J13: Delta 8 Infused (40MG) | K13: R30 | L13: 30 count blue raspberry
A14: Strawberry Delta 8 Gummies (30CT) | B14: =F14&": "&H14&", "&J14&", "&L14 -> Edible: Gummies, Delta 8 Infused (40MG), 30 count strawberry | C14: E-StrawberryD8Gummies30Ct | D14: =E14&G14&I14&K14 -> 338S30 | E14: 3 | F14: Edible | G14: 3 | H14: Gummies | I14: 8 | J14: Delta 8 Infused (40MG) | K14: S30 | L14: 30 count strawberry
A15: Supreme Formula (60mg CBD) Gummies (10ct) | C15: E-Supreme Gummies10Ct
A16: Supreme Formula (60mg CBD) Gummies (30ct) | C16: E-Supreme Gummies30Ct
A17: 100 Pack Honeysticks | B17: =F17&": "&H17&", "&J17&", "&L17 -> Edible: Hemp Honey Sticks, Original Formula, 100 Pack | C17: E-Honey100 | D17: =E17&G17&I17&K17 -> 3114 | E17: 3 | F17: Edible | G17: 1 | H17: Hemp Honey Sticks | I17: 1 | J17: Original Formula | K17: 4 | L17: 100 Pack
A18: 20 Pack Honeysticks | B18: =F18&": "&H18&", "&J18&", "&L18 -> Edible: Hemp Honey Sticks, Original Formula, 20 Pack | C18: E-Honey20 | D18: =E18&G18&I18&K18 -> 3112 | E18: 3 | F18: Edible | G18: 1 | H18: Hemp Honey Sticks | I18: 1 | J18: Original Formula | K18: 2 | L18: 20 Pack
B19: =F19&": "&H19&", "&J19&", "&L19 -> Edible: Hemp Honey Sticks, Original Formula, 5 Pack | D19: =E19&G19&I19&K19 -> 3113 | E19: 3 | F19: Edible | G19: 1 | H19: Hemp Honey Sticks | I19: 1 | J19: Original Formula | K19: 3 | L19: 5 Pack
A20: Honey Stick | B20: =F20&": "&H20&", "&J20&", "&L20 -> Edible: Hemp Honey Sticks, Original Formula, Individual Stick | C20: E-Honeystick | D20: =E20&G20&I20&K20 -> 3111 | E20: 3 | F20: Edible | G20: 1 | H20: Hemp Honey Sticks | I20: 1 | J20: Original Formula | K20: 1 | L20: Individual Stick
A21: Caramel Taffies | B21: =F21&": "&H21&", "&J21&", "&L21 -> Edible: Saltwater Taffy, 1.28g extract per lb, 5g taffy with caramel flavoring, Single Serving | C21: E-Taffy | D21: =E21&G21&I21&K21 -> 3211 | E21: 3 | F21: Edible | G21: 2 | H21: Saltwater Taffy | I21: 1 | J21: 1.28g extract per lb, 5g taffy with caramel flavoring | K21: 1 | L21: Single Serving
A22: THC Free Taffies 50 Pack | B22: =F22&": "&H22&", "&J22&", "&L22 -> Edible: Saltwater Taffy, 1.4g CBD Isolate per lb, 5g taffy with caramel flavoring, 50 Pack | C22: 3224 | D22: 3224 | E22: 3 | F22: Edible | G22: 2 | H22: Saltwater Taffy | I22: 2 | J22: 1.4g CBD Isolate per lb, 5g taffy with caramel flavoring | K22: 4 | L22: 50 Pack
B23: =F23&": "&H23&", "&J23&", "&L23 -> Edible: Saltwater Taffy, 1.5g extract per lb, 5g taffy with caramel flavoring, 10 Pack | D23: =E23&G23&I23&K23 -> 3212 | E23: 3 | F23: Edible | G23: 2 | H23: Saltwater Taffy | I23: 1 | J23: 1.5g extract per lb, 5g taffy with caramel flavoring | K23: 2 | L23: 10 Pack
A24: 20 Pack Taffies | B24: =F24&": "&H24&", "&J24&", "&L24 -> Edible: Saltwater Taffy, 1.5g extract per lb, 5g taffy with caramel flavoring, 20 Pack | C24: E-Taffy20 | D24: =E24&G24&I24&K24 -> 3213 | E24: 3 | F24: Edible | G24: 2 | H24: Saltwater Taffy | I24: 1 | J24: 1.5g extract per lb, 5g taffy with caramel flavoring | K24: 3 | L24: 20 Pack
A25: Caramel Taffies 50 Pack | B25: =F25&": "&H25&", "&J25&", "&L25 -> Edible: Saltwater Taffy, 1.5g extract per lb, 5g taffy with caramel flavoring, 50 Pack | C25: E-Taffy50 | D25: =E25&G25&I25&K25 -> 3214 | E25: 3 | F25: Edible | G25: 2 | H25: Saltwater Taffy | I25: 1 | J25: 1.5g extract per lb, 5g taffy with caramel flavoring | K25: 4 | L25: 50 Pack
A26: Lemon Cream Taffies, 50 Pack | B26: =F26&": "&H26&", "&J26&", "&L26 -> Edible: Saltwater Taffy, 1.5g extract per lb, 5g taffy with lemon flavor, 50 Pack | C26: E-Lemon-Taffies50 | D26: E-LemonTaffies50 | E26: 3 | F26: Edible | G26: 2 | H26: Saltwater Taffy | I26: 4 | J26: 1.5g extract per lb, 5g taffy with lemon flavor | K26: 4 | L26: 50 Pack
A27: Peanut Butter Taffies 50 Pack | B27: =F27&": "&H27&", "&J27&", "&L27 -> Edible: Saltwater Taffy, 1.5g extract per lb, 5g taffy with peanut butter flavor, 50 Pack | C27: 3234 | D27: =E27&G27&I27&K27 -> 3234 | E27: 3 | F27: Edible | G27: 2 | H27: Saltwater Taffy | I27: 3 | J27: 1.5g extract per lb, 5g taffy with peanut butter flavor | K27: 4 | L27: 50 Pack
A28: Strong D8 THC Taffies (42mg/taffy), 20 pack | B28: =F28&": "&H28&", "&J28&", "&L28 -> Edible: Saltwater Taffy, 10.9g 85% D8 distillate per lb-taffy, 20 Pack | C28: E-D8StrongTaffies20 | E28: 3 | F28: Edible | G28: 2 | H28: Saltwater Taffy | I28: 5 | J28: 10.9g 85% D8 distillate per lb-taffy | K28: 3 | L28: 20 Pack
A29: 60 ct gelcaps | B29: =F29&": "&H29&", "&J29&", "&L29 -> Other: Gelcaps, Advanced Formula 1/2mL gelcaps (22 mg/gelcap), 30 ct bottle | C29: E-30Softgels | D29: =E29&G29&I29&K29 -> 0112 | E29: 0 | F29: Other | G29: 1 | H29: Gelcaps | I29: 1 | J29: Advanced Formula 1/2mL gelcaps (22 mg/gelcap) | K29: 2 | L29: 30 ct bottle
A30: 30ct gelcaps | B30: =F30&": "&H30&", "&J30&", "&L30 -> Other: Gelcaps, Advanced Formula 1/2mL gelcaps (22 mg/gelcap), 60 ct bottle | C30: E-60Softgels | D30: =E30&G30&I30&K30 -> 0111 | E30: 0 | F30: Other | G30: 1 | H30: Gelcaps | I30: 1 | J30: Advanced Formula 1/2mL gelcaps (22 mg/gelcap) | K30: 1 | L30: 60 ct bottle
B31: =F31&": "&H31&", "&J31&", "&L31 -> Other: Transaction Costs, Payment Processing Fee, Credit Card | D31: =E31&G31&I31&K31 -> 0020 | E31: 0 | F31: Other | G31: 0 | H31: Transaction Costs | I31: 2 | J31: Payment Processing Fee | K31: 0 | L31: Credit Card
B32: =F32&": "&H32&", "&J32&", "&L32 -> Other: Transaction Costs, Shipping, Overnight | D32: =E32&G32&I32&K32 -> 0012 | E32: 0 | F32: Other | G32: 0 | H32: Transaction Costs | I32: 1 | J32: Shipping | K32: 2 | L32: Overnight
B33: =F33&": "&H33&", "&J33&", "&L33 -> Other: Transaction Costs, Shipping, UPS | D33: =E33&G33&I33&K33 -> 0011 | E33: 0 | F33: Other | G33: 0 | H33: Transaction Costs | I33: 1 | J33: Shipping | K33: 1 | L33: UPS
B34: =F34&": "&H34&", "&J34&", "&L34 -> Other: Transaction Costs, Shipping, USPS | D34: =E34&G34&I34&K34 -> 0010 | E34: 0 | F34: Other | G34: 0 | H34: Transaction Costs | I34: 1 | J34: Shipping | K34: 0 | L34: USPS
B35: =F35&": "&H35&", "&J35&", "&L35 -> Other: Uncategorized, , | D35: =E35&G35&I35&K35 -> 0900 | E35: 0 | F35: Other | G35: 9 | H35: Uncategorized | I35: 0 | K35: 0
A36: Peanut Butter Pet Tincture | B36: Peanut Butter Pet Tincture, 1oz | C36: T-1PetPB | D36: T-1PetPB
B37: =F37&": "&H37&", "&J37&", "&L37 -> Pet: Dog Treats, Original Formula (wheat flour base, 5mg CBD per treat), 20 Pack | D37: =E37&G37&I37&K37 -> 7111 | E37: 7 | F37: Pet | G37: 1 | H37: Dog Treats | I37: 1 | J37: Original Formula (wheat flour base, 5mg CBD per treat) | K37: 1 | L37: 20 Pack
A38: Pet Tincture | B38: =F38&": "&H38&", "&J38&", "&L38 -> Pet: Tincture, Original Formula, 1oz | C38: T-1Pets | D38: =E38&G38&I38&K38 -> 7211 | E38: 7 | F38: Pet | G38: 2 | H38: Tincture | I38: 1 | J38: Original Formula | K38: 1 | L38: 1oz
B39: =F39&": "&H39&", "&J39&", "&L39 -> Special: Apparel, T-Shirts, Original NSB Shirt | D39: =E39&G39&I39&K39 -> 5311 | E39: 5 | F39: Special | G39: 3 | H39: Apparel | I39: 1 | J39: T-Shirts | K39: 1 | L39: Original NSB Shirt
B40: =F40&": "&H40&", "&J40&", "&L40 -> Special: Educational Materials, "How to Think About Hemp Flower Extract" trifold brochure, Default | D40: =E40&G40&I40&K40 -> 5111 | E40: 5 | F40: Special | G40: 1 | H40: Educational Materials | I40: 1 | J40: "How to Think About Hemp Flower Extract" trifold brochure | K40: 1 | L40: Default
...

Sheet Key
B1: XXYYZZAA
B2: XX is For Type (Vapor, Tincture, Edible, etc) | H2: BB Codes
B3: YY if For Product Type (Vape Pod, Cartridge, etc -- loose classification here honestly) | H3: -S | I3: Sample (Marked)
B4: ZZ if for Product Variation
B5: AA if for quantity
B6: BB for addendum (suffixes, etc)

Sheet Inputs
A1: XXYYZZAA
A3: Juul Pod Kits
A4: 1mL Ceramic Cartridges
A5: BBTank Flip Batteries
A6: 1oz Boston Bottles
A7: 2oz Boston Bottles
A8: 1/2oz Boston Bottles
A9: Heat Shrink Wrap for Bottles

Sheet SKU-Product List
A1: SKU | B1: Description | C1: Category | D1: Short Name
A2: =Products!D3 -> 8112 | B2: =Products!B3 -> Bundle: Bundles, Lotion Bar, Honeysticks plus tincture, 1400mg | C2: =Products!F3 -> Bundle | D2: Vape Pod System, Raw
A3: =Products!D4 -> 8111 | B3: =Products!B4 -> Bundle: Bundles, Lotion Bar, Honeysticks plus tincture, 2800mg | C3: =Products!F4 -> Bundle | D3: Vape Pod System, Fresh
A4: =Products!D5 -> 8113 | B4: =Products!B5 -> Bundle: Bundles, Lotion Bar, Honeysticks plus tincture, 700mg | C4: =Products!F5 -> Bundle | D4: 510 Vape Cart Refill, Raw
A5: =Products!D6 -> 8221 | B5: =Products!B6 -> Bundle: Gift Packs, 1/2oz adv tincture, 1 lotion bar, 10 taffies, Default | C5: =Products!F6 -> Bundle | D5: =B5 -> Bundle: Gift Packs, 1/2oz adv tincture, 1 lotion bar, 10 taffies, Default
A6: =Products!D7 -> 8211 | B6: =Products!B7 -> Bundle: Gift Packs, 30 ct gelcaps, 1 lotion bar, 10 taffies, Default | C6: =Products!F7 -> Bundle | D6: 510 Vape Cart Refill, Fresh
A7: =Products!D8 -> 8211 | B7: =Products!B8 -> Bundle: Gift Packs, taffies and lotion bar plus another product, 1/2oz advanced tincture | C7: =Products!F8 -> Bundle | D7: =B7 -> Bundle: Gift Packs, taffies and lotion bar plus another product, 1/2oz advanced tincture
A8: =Products!D9 -> 8212 | B8: =Products!B9 -> Bundle: Gift Packs, taffies and lotion bar plus another product, 30ct advanced gelcaps | C8: =Products!F9 -> Bundle | D8: Juul Compatible Vape Cartridge, Raw
A9: =Products!D10 -> 8111 | B9: =Products!B10 -> Bundle: Starter Packs, Gold Package (2800, lotion bar & honeysticks), Default | C9: =Products!F10 -> Bundle | D9: Juul Compatible Vape Cartridge, Fresh
A10: =Products!D17 -> 3114 | B10: =Products!B17 -> Edible: Hemp Honey Sticks, Original Formula, 100 Pack | C10: =Products!F17 -> Edible | D10: =B10 -> Edible: Hemp Honey Sticks, Original Formula, 100 Pack
A11: =Products!D18 -> 3112 | B11: =Products!B18 -> Edible: Hemp Honey Sticks, Original Formula, 20 Pack | C11: =Products!F18 -> Edible | D11: =B11 -> Edible: Hemp Honey Sticks, Original Formula, 20 Pack
A12: =Products!D20 -> 3111 | B12: =Products!B20 -> Edible: Hemp Honey Sticks, Original Formula, Individual Stick | C12: =Products!F20 -> Edible | D12: =B12 -> Edible: Hemp Honey Sticks, Original Formula, Individual Stick
A13: =Products!D21 -> 3211 | B13: =Products!B21 -> Edible: Saltwater Taffy, 1.28g extract per lb, 5g taffy with caramel flavoring, Single Serving | C13: =Products!F21 -> Edible | D13: =B13 -> Edible: Saltwater Taffy, 1.28g extract per lb, 5g taffy with caramel flavoring, Single Serving
A14: =Products!D22 -> 3224 | B14: =Products!B22 -> Edible: Saltwater Taffy, 1.4g CBD Isolate per lb, 5g taffy with caramel flavoring, 50 Pack | C14: =Products!F22 -> Edible | D14: =B14 -> Edible: Saltwater Taffy, 1.4g CBD Isolate per lb, 5g taffy with caramel flavoring, 50 Pack
A15: =Products!D23 -> 3212 | B15: =Products!B23 -> Edible: Saltwater Taffy, 1.5g extract per lb, 5g taffy with caramel flavoring, 10 Pack | C15: =Products!F23 -> Edible | D15: 5mL Vape Juice (20% CBD, Raw Flavor)
A16: =Products!D24 -> 3213 | B16: =Products!B24 -> Edible: Saltwater Taffy, 1.5g extract per lb, 5g taffy with caramel flavoring, 20 Pack | C16: =Products!F24 -> Edible | D16: 5mL Vape Juice (20% CBD, Fresh Flavor)
A17: =Products!D25 -> 3214 | B17: =Products!B25 -> Edible: Saltwater Taffy, 1.5g extract per lb, 5g taffy with caramel flavoring, 50 Pack | C17: =Products!F25 -> Edible | D17: 5mL Vape Juice (40% CBD, Raw Flavor)
A18: =Products!D26 -> E-LemonTaffies50 | B18: =Products!B26 -> Edible: Saltwater Taffy, 1.5g extract per lb, 5g taffy with lemon flavor, 50 Pack | C18: =Products!F26 -> Edible | D18: 5mL Vape Juice (40% CBD, Fresh Flavor)
A19: =Products!D27 -> 3234 | B19: =Products!B27 -> Edible: Saltwater Taffy, 1.5g extract per lb, 5g taffy with peanut butter flavor, 50 Pack | C19: =Products!F27 -> Edible | D19: =B19 -> Edible: Saltwater Taffy, 1.5g extract per lb, 5g taffy with peanut butter flavor, 50 Pack
A20: =Products!D28 | B20: =Products!B28 -> Edible: Saltwater Taffy, 10.9g 85% D8 distillate per lb-taffy, 20 Pack | C20: =Products!F28 -> Edible | D20: Original Formula, 1oz (450mg)
A21: =Products!D29 -> 0112 | B21: =Products!B29 -> Other: Gelcaps, Advanced Formula 1/2mL gelcaps (22 mg/gelcap), 30 ct bottle | C21: =Products!F29 -> Other | D21: =B21 -> Other: Gelcaps, Advanced Formula 1/2mL gelcaps (22 mg/gelcap), 30 ct bottle
A22: =Products!D31 -> 0020 | B22: =Products!B31 -> Other: Transaction Costs, Payment Processing Fee, Credit Card | C22: =Products!F31 -> Other | D22: Original Formula Tincture, 2oz (900mg)
A23: =Products!D32 -> 0012 | B23: =Products!B32 -> Other: Transaction Costs, Shipping, Overnight | C23: =Products!F32 -> Other | D23: Original Formula Tincture, 1/2 oz (225mg)
A24: =Products!D33 -> 0011 | B24: =Products!B33 -> Other: Transaction Costs, Shipping, UPS | C24: =Products!F33 -> Other | D24: Advanced Formula Tincture, 1oz (1400mg)
A25: =Products!D36 -> T-1PetPB | B25: =Products!B36 -> Peanut Butter Pet Tincture, 1oz | C25: =Products!F36 | D25: Advanced Formula Tincture, 1oz (1400mg)
A26: =Products!D37 -> 7111 | B26: =Products!B37 -> Pet: Dog Treats, Original Formula (wheat flour base, 5mg CBD per treat), 20 Pack | C26: =Products!F37 -> Pet | D26: Advanced Formula Tincture, 16oz (22,400mg)
A27: =Products!D39 -> 5311 | B27: =Products!B39 -> Special: Apparel, T-Shirts, Original NSB Shirt | C27: =Products!F39 -> Special | D27: Advanced Formula Tincture, 1/2 oz (700mg)
A28: =Products!D40 -> 5111 | B28: =Products!B40 -> Special: Educational Materials, "How to Think About Hemp Flower Extract" trifold brochure, Default | C28: =Products!F40 -> Special | D28: =B28 -> Special: Educational Materials, "How to Think About Hemp Flower Extract" trifold brochure, Default
A29: =Products!D41 -> 5131 | B29: =Products!B41 -> Special: Educational Materials, Coozies, General | C29: =Products!F41 -> Special | D29: Supreme Formula Tincture, 1oz (3900mg)
A30: =Products!D44 -> 5221 | B30: =Products!B44 -> Special: Retail Displays, Three-Tier Plexi- Glass Display Case, Default | C30: =Products!F44 -> Special | D30: =B30 -> Special: Retail Displays, Three-Tier Plexi- Glass Display Case, Default
A31: =Products!D45 -> 5211 | B31: =Products!B45 -> Special: Retail Displays, Trifold Brochure Holder, Default | C31: =Products!F45 -> Special | D31: Hemp Honey Sticks, 20 pack
A32: =Products!D46 -> 5411 | B32: =Products!B46 -> Special: Service Charges, CC Convenience Fee, Default | C32: =Products!F46 -> Special | D32: =B32 -> Special: Service Charges, CC Convenience Fee, Default
A33: =Products!D47 -> 2211 | B33: =Products!B47 -> Tincture: Advanced Formula, Mint Chocolate Flavor, 1oz (30mL) | C33: =Products!F47 -> Tincture | D33: Hemp Honey Sticks, 100 pack
A34: =Products!D48 -> 2203 | B34: =Products!B48 -> Tincture: Advanced Formula, No Additives, 1/2oz (15mL) | C34: =Products!F48 -> Tincture | D34: =B34 -> Tincture: Advanced Formula, No Additives, 1/2oz (15mL)
A35: =Products!D49 -> 2205 | B35: =Products!B49 -> Tincture: Advanced Formula, No Additives, 16oz | C35: =Products!F49 -> Tincture | D35: =B35 -> Tincture: Advanced Formula, No Additives, 16oz
A36: =Products!D50 -> 2201 | B36: =Products!B50 -> Tincture: Advanced Formula, No Additives, 1oz (30mL) | C36: =Products!F50 -> Tincture | D36: =B36 -> Tincture: Advanced Formula, No Additives, 1oz (30mL)
A37: =Products!D51 -> 2204 | B37: =Products!B51 -> Tincture: Advanced Formula, No Additives, 1oz and 2oz bottles | C37: =Products!F51 -> Tincture | D37: Hemp Flower Extract Infused Saltwater Taffies, 50ct
A38: =Products!D55 -> 2111 | B38: =Products!B55 -> Tincture: Original Formula, Mint Chocolate Flavor, 1oz (30mL) | C38: =Products!F55 -> Tincture | D38: =B38 -> Tincture: Original Formula, Mint Chocolate Flavor, 1oz (30mL)
A39: =Products!D56 -> 2103 | B39: =Products!B56 -> Tincture: Original Formula, No Additives, 1/2oz (15mL) | C39: =Products!F56 -> Tincture | D39: =B39 -> Tincture: Original Formula, No Additives, 1/2oz (15mL)
A40: =Products!D57 -> 2101 | B40: =Products!B57 -> Tincture: Original Formula, No Additives, 1oz (30mL) | C40: =Products!F57 -> Tincture | D40: =B40 -> Tincture: Original Formula, No Additives, 1oz (30mL)
...

Sheet QBO Items
A1: QBO Description | B1: SKU | C1: SKU as String | D1: Description | E1: Category
A2: B. Vapor:Vape Pod System with pre-filled 1mL cartridge (400+ MG), Fresh Flavor (deleted) | B2: 1111 | C2: =TEXT(B2, "0") -> 1111 | D2: =VLOOKUP(C2, 'SKU-Product List'!$A$2:$C$420, 2, FALSE) -> Vapor: Vape Pod System, Raw Flavor, 1mL (400mg) | E2: =VLOOKUP(C2, 'SKU-Product List'!$A$2:$C$420, 3, FALSE) -> Vapor
A3: B. Vapor:Pre-filled 1mL vaporizer cartridge - Raw Flavor (400+ MG) | B3: 1211 | C3: =TEXT(B3, "0") -> 1211 | D3: =VLOOKUP(C3, 'SKU-Product List'!$A$2:$C$420, 2, FALSE) -> Vapor: 510 Refill, Raw Flavor, 1mL (400mg) | E3: =VLOOKUP(C3, 'SKU-Product List'!$A$2:$C$420, 3, FALSE) -> Vapor
A4: B. Vapor:Pre-filled 1mL vaporizer cartridge - Fresh Flavor (400+ MG), | B4: 1221 | C4: =TEXT(B4, "0") -> 1221 | D4: =VLOOKUP(C4, 'SKU-Product List'!$A$2:$C$420, 2, FALSE) -> Vapor: 510 Refill, Fresh Flavor, 1mL (400mg) | E4: =VLOOKUP(C4, 'SKU-Product List'!$A$2:$C$420, 3, FALSE) -> Vapor
A5: B. Vapor:Vape Pod System with pre-filled 1mL cartridge (400+ MG), Raw Flavor (deleted) | B5: 1111 | C5: =TEXT(B5, "0") -> 1111 | D5: =VLOOKUP(C5, 'SKU-Product List'!$A$2:$C$420, 2, FALSE) -> Vapor: Vape Pod System, Raw Flavor, 1mL (400mg) | E5: =VLOOKUP(C5, 'SKU-Product List'!$A$2:$C$420, 3, FALSE) -> Vapor
A6: E. Shipping:USPS Shipping | B6: 10 | C6: ="0010" -> 0010 | D6: =VLOOKUP(C6, 'SKU-Product List'!$A$2:$C$420, 2, FALSE) -> #N/A | E6: =VLOOKUP(C6, 'SKU-Product List'!$A$2:$C$420, 3, FALSE) -> #N/A
A7: D. Honey:(100pack) Hemp Honey Sticks 15mg | B7: 3114 | C7: =TEXT(B7, "0") -> 3114 | D7: =VLOOKUP(C7, 'SKU-Product List'!$A$2:$C$420, 2, FALSE) -> Edible: Hemp Honey Sticks, Original Formula, 100 Pack | E7: =VLOOKUP(C7, 'SKU-Product List'!$A$2:$C$420, 3, FALSE) -> Edible
A8: A. Tinctures:2oz (2800MG) Advanced Hemp Flower Extract | B8: 2202 | C8: =TEXT(B8, "0") -> 2202 | D8: =VLOOKUP(C8, 'SKU-Product List'!$A$2:$C$420, 2, FALSE) -> #N/A | E8: =VLOOKUP(C8, 'SKU-Product List'!$A$2:$C$420, 3, FALSE) -> #N/A
A9: A. Tinctures:1oz (1400MG) Advanced Hemp Flower Extract | B9: 2201 | C9: =TEXT(B9, "0") -> 2201 | D9: =VLOOKUP(C9, 'SKU-Product List'!$A$2:$C$420, 2, FALSE) -> Tincture: Advanced Formula, No Additives, 1oz (30mL) | E9: =VLOOKUP(C9, 'SKU-Product List'!$A$2:$C$420, 3, FALSE) -> Tincture
A10: A. Tinctures:2oz (900MG) Hemp Flower Extract | B10: 2102 | C10: =TEXT(B10, "0") -> 2102 | D10: =VLOOKUP(C10, 'SKU-Product List'!$A$2:$C$420, 2, FALSE) -> Tincture: Original Formula, No Additives, 2oz (60mL) | E10: =VLOOKUP(C10, 'SKU-Product List'!$A$2:$C$420, 3, FALSE) -> Tincture
A11: A. Tinctures:1oz (450MG) Hemp Flower Extract | B11: 2101 | C11: =TEXT(B11, "0") -> 2101 | D11: =VLOOKUP(C11, 'SKU-Product List'!$A$2:$C$420, 2, FALSE) -> Tincture: Original Formula, No Additives, 1oz (30mL) | E11: =VLOOKUP(C11, 'SKU-Product List'!$A$2:$C$420, 3, FALSE) -> Tincture
A12: E. Shipping:UPS Shipping | B12: 11 | C12: ="0011" -> 0011 | D12: =VLOOKUP(C12, 'SKU-Product List'!$A$2:$C$420, 2, FALSE) -> Other: Transaction Costs, Shipping, UPS | E12: =VLOOKUP(C12, 'SKU-Product List'!$A$2:$C$420, 3, FALSE) -> Other
A13: B. Vapor:(2000mg) Raw Vape Fluid Bottle | B13: 1411 | C13: =TEXT(B13, "0") -> 1411 | D13: =VLOOKUP(C13, 'SKU-Product List'!$A$2:$C$420, 2, FALSE) -> Vapor: Vape Juice, Raw Flavor, 40% CBD (2000mg) | E13: =VLOOKUP(C13, 'SKU-Product List'!$A$2:$C$420, 3, FALSE) -> Vapor
A14: B. Vapor:(2000mg) Fresh Vape Fluid Bottle | B14: 1421 | C14: =TEXT(B14, "0") -> 1421 | D14: =VLOOKUP(C14, 'SKU-Product List'!$A$2:$C$420, 2, FALSE) -> Vapor: Vape Juice, Fresh Flavor, 40% CBD (2000mg) | E14: =VLOOKUP(C14, 'SKU-Product List'!$A$2:$C$420, 3, FALSE) -> Vapor
A15: G. Other:Credit Processing:Convenience fee (Credit Processing) | B15: 20 | C15: ="0020" -> 0020 | D15: =VLOOKUP(C15, 'SKU-Product List'!$A$2:$C$420, 2, FALSE) -> Other: Transaction Costs, Payment Processing Fee, Credit Card | E15: =VLOOKUP(C15, 'SKU-Product List'!$A$2:$C$420, 3, FALSE) -> Other
A16: A. Tinctures:0.5oz (700MG) Advanced Hemp Flower Extract | B16: 2201 | C16: =TEXT(B16, "0") -> 2201 | D16: =VLOOKUP(C16, 'SKU-Product List'!$A$2:$C$420, 2, FALSE) -> Tincture: Advanced Formula, No Additives, 1oz (30mL) | E16: =VLOOKUP(C16, 'SKU-Product List'!$A$2:$C$420, 3, FALSE) -> Tincture
A17: A. Tinctures:0.5oz (225MG) Hemp Flower Extract | B17: 2103 | C17: =TEXT(B17, "0") -> 2103 | D17: =VLOOKUP(C17, 'SKU-Product List'!$A$2:$C$420, 2, FALSE) -> Tincture: Original Formula, No Additives, 1/2oz (15mL) | E17: =VLOOKUP(C17, 'SKU-Product List'!$A$2:$C$420, 3, FALSE) -> Tincture
A18: F. Educational Materials:Trifold Brochure | B18: 5211 | C18: =TEXT(B18, "0") -> 5211 | D18: =VLOOKUP(C18, 'SKU-Product List'!$A$2:$C$420, 2, FALSE) -> Special: Retail Displays, Trifold Brochure Holder, Default | E18: =VLOOKUP(C18, 'SKU-Product List'!$A$2:$C$420, 3, FALSE) -> Special
A19: B. Vapor:Escape Pods (4 Juul-compatible cartridges with 280mg CBD each) (deleted) | B19: 1315 | C19: =TEXT(B19, "0") -> 1315 | D19: =VLOOKUP(C19, 'SKU-Product List'!$A$2:$C$420, 2, FALSE) -> Vapor: Escape Pod, Raw Flavor, 4-Pack | E19: =VLOOKUP(C19, 'SKU-Product List'!$A$2:$C$420, 3, FALSE) -> Vapor
A20: B. Vapor:Escape Pod - Fresh Flavor (1 Juul-compatible cartridge with 280mg CBD) | B20: 1323 | C20: =TEXT(B20, "0") -> 1323 | D20: =VLOOKUP(C20, 'SKU-Product List'!$A$2:$C$420, 2, FALSE) -> Vapor: Escape Pod, Fresh Flavor, 1-Pack | E20: =VLOOKUP(C20, 'SKU-Product List'!$A$2:$C$420, 3, FALSE) -> Vapor
A21: B. Vapor:Escape Pod - Raw Flavor (1 Juul-compatible cartridge with 280mg CBD) | B21: 1313 | C21: =TEXT(B21, "0") -> 1313 | D21: =VLOOKUP(C21, 'SKU-Product List'!$A$2:$C$420, 2, FALSE) -> Vapor: Escape Pod, Raw Flavor, 1-Pack | E21: =VLOOKUP(C21, 'SKU-Product List'!$A$2:$C$420, 3, FALSE) -> Vapor
A22: C. Topicals:Lotion Bar (100mg) | B22: 6231 | C22: =TEXT(B22, "0") -> 6231 | D22: =VLOOKUP(C22, 'SKU-Product List'!$A$2:$C$420, 2, FALSE) -> Topical: Lotion, Original Formula, Individual (0.5oz bar) | E22: =VLOOKUP(C22, 'SKU-Product List'!$A$2:$C$420, 3, FALSE) -> Topical
A23: D. Honey:(20 Pack) Honey Sticks | B23: 3112 | C23: =TEXT(B23, "0") -> 3112 | D23: =VLOOKUP(C23, 'SKU-Product List'!$A$2:$C$420, 2, FALSE) -> Edible: Hemp Honey Sticks, Original Formula, 20 Pack | E23: =VLOOKUP(C23, 'SKU-Product List'!$A$2:$C$420, 3, FALSE) -> Edible
A24: C. Topicals:Lip Balm (50mg) | B24: 6131 | C24: =TEXT(B24, "0") -> 6131 | D24: =VLOOKUP(C24, 'SKU-Product List'!$A$2:$C$420, 2, FALSE) -> Topical: Balm, Original Formula, Individual (0.15oz tube) | E24: =VLOOKUP(C24, 'SKU-Product List'!$A$2:$C$420, 3, FALSE) -> Topical
A25: E. Shipping:Overnight shipping (+$35.00) | B25: 12 | C25: ="0012" -> 0012 | D25: =VLOOKUP(C25, 'SKU-Product List'!$A$2:$C$420, 2, FALSE) -> Other: Transaction Costs, Shipping, Overnight | E25: =VLOOKUP(C25, 'SKU-Product List'!$A$2:$C$420, 3, FALSE) -> Other
A26: B. Vapor:4-Pack Escape Pods - Fresh Flavor (4 Juul-compatible cartridge with 280mg CBD) | B26: 1325 | C26: =TEXT(B26, "0") -> 1325 | D26: =VLOOKUP(C26, 'SKU-Product List'!$A$2:$C$420, 2, FALSE) -> Vapor: Escape Pod, Fresh Flavor, 4-Pack | E26: =VLOOKUP(C26, 'SKU-Product List'!$A$2:$C$420, 3, FALSE) -> Vapor
A27: B. Vapor:4-Pack Escape Pods - Raw Flavor (4 Juul-compatible cartridge with 280mg CBD) | B27: 1315 | C27: =TEXT(B27, "0") -> 1315 | D27: =VLOOKUP(C27, 'SKU-Product List'!$A$2:$C$420, 2, FALSE) -> Vapor: Escape Pod, Raw Flavor, 4-Pack | E27: =VLOOKUP(C27, 'SKU-Product List'!$A$2:$C$420, 3, FALSE) -> Vapor
A28: G. Other:Display Case (3 Tier) | B28: 5221 | C28: =TEXT(B28, "0") -> 5221 | D28: =VLOOKUP(C28, 'SKU-Product List'!$A$2:$C$420, 2, FALSE) -> Special: Retail Displays, Three-Tier Plexi- Glass Display Case, Default | E28: =VLOOKUP(C28, 'SKU-Product List'!$A$2:$C$420, 3, FALSE) -> Special
A29: G. Other:Tech:VAPE BATTERY 350mAH | B29: 1511 | C29: =TEXT(B29, "0") -> 1511 | D29: =VLOOKUP(C29, 'SKU-Product List'!$A$2:$C$420, 2, FALSE) -> Vapor: Hardware Only, 350mAH, button battery, The one that says "CBD" | E29: =VLOOKUP(C29, 'SKU-Product List'!$A$2:$C$420, 3, FALSE) -> Vapor
A30: D. Honey:20 Pack Honeysticks (Retail Only) (deleted) | B30: 3112 | C30: =TEXT(B30, "0") -> 3112 | D30: =VLOOKUP(C30, 'SKU-Product List'!$A$2:$C$420, 2, FALSE) -> Edible: Hemp Honey Sticks, Original Formula, 20 Pack | E30: =VLOOKUP(C30, 'SKU-Product List'!$A$2:$C$420, 3, FALSE) -> Edible
A31: G. Other:Tech:Variable Voltage Vape Battery (Single) | B31: 1511 | C31: =TEXT(B31, "0") -> 1511 | D31: =VLOOKUP(C31, 'SKU-Product List'!$A$2:$C$420, 2, FALSE) -> Vapor: Hardware Only, 350mAH, button battery, The one that says "CBD" | E31: =VLOOKUP(C31, 'SKU-Product List'!$A$2:$C$420, 3, FALSE) -> Vapor
A32: G. Other:Apparel:NSB Shirt | B32: 5311 | C32: =TEXT(B32, "0") -> 5311 | D32: =VLOOKUP(C32, 'SKU-Product List'!$A$2:$C$420, 2, FALSE) -> Special: Apparel, T-Shirts, Original NSB Shirt | E32: =VLOOKUP(C32, 'SKU-Product List'!$A$2:$C$420, 3, FALSE) -> Special
A33: F. Educational Materials:NSB Poster (Mountain Version) | B33: 5121 | C33: =TEXT(B33, "0") -> 5121 | D33: =VLOOKUP(C33, 'SKU-Product List'!$A$2:$C$420, 2, FALSE) -> #N/A | E33: =VLOOKUP(C33, 'SKU-Product List'!$A$2:$C$420, 3, FALSE) -> #N/A
A34: B. Vapor:(1000mg) Fresh Vape Fluid Bottle | B34: 1422 | C34: =TEXT(B34, "0") -> 1422 | D34: =VLOOKUP(C34, 'SKU-Product List'!$A$2:$C$420, 2, FALSE) -> Vapor: Vape Juice, Fresh Flavor, 20% CBD (1000mg) | E34: =VLOOKUP(C34, 'SKU-Product List'!$A$2:$C$420, 3, FALSE) -> Vapor
A35: B. Vapor:Vape Pod System - Raw Flavor with pre-filled 1mL cartridge (400+ MG) (deleted) | B35: 1111 | C35: =TEXT(B35, "0") -> 1111 | D35: =VLOOKUP(C35, 'SKU-Product List'!$A$2:$C$420, 2, FALSE) -> Vapor: Vape Pod System, Raw Flavor, 1mL (400mg) | E35: =VLOOKUP(C35, 'SKU-Product List'!$A$2:$C$420, 3, FALSE) -> Vapor
A36: B. Vapor:Vape Pod System - Fresh Flavor with pre-filled 1mL cartridge (400+ MG) (deleted) | B36: 1121 | C36: =TEXT(B36, "0") -> 1121 | D36: =VLOOKUP(C36, 'SKU-Product List'!$A$2:$C$420, 2, FALSE) -> Vapor: Vape Pod System, Fresh Flavor, 1mL (400mg) | E36: =VLOOKUP(C36, 'SKU-Product List'!$A$2:$C$420, 3, FALSE) -> Vapor
A37: F. Educational Materials:NSB Poster (Beach Version) | B37: 5122 | C37: =TEXT(B37, "0") -> 5122 | D37: =VLOOKUP(C37, 'SKU-Product List'!$A$2:$C$420, 2, FALSE) -> #N/A | E37: =VLOOKUP(C37, 'SKU-Product List'!$A$2:$C$420, 3, FALSE) -> #N/A
... A42: C. Topicals:Hot Muscle Rub (100MG) | B42: 6221 | C42: =TEXT(B42, "0") -> 6221 | D42: =VLOOKUP(C42, 'SKU-Product List'!$A$2:$C$420, 2, FALSE) -> #N/A | E42: =VLOOKUP(C42, 'SKU-Product List'!$A$2:$C$420, 3, FALSE) -> #N/A
A43: E. Shipping:USPS Standard Shipping | C43: ="0010" -> 0010 | D43: =VLOOKUP(C43, 'SKU-Product List'!$A$2:$C$420, 2, FALSE) -> #N/A | E43: =VLOOKUP(C43, 'SKU-Product List'!$A$2:$C$420, 3, FALSE) -> #N/A
A44: A. Tinctures:Pet Tincture 425MG | B44: 7211 | C44: =TEXT(B44, "0") -> 7211 | D44: =VLOOKUP(C44, 'SKU-Product List'!$A$2:$C$420, 2, FALSE) -> #N/A | E44: =VLOOKUP(C44, 'SKU-Product List'!$A$2:$C$420, 3, FALSE) -> #N/A
...
